<?xml version="1.0" encoding="utf-8"?>
<!-- =================================================================================== -->
<!-- |    This document was autogenerated by xacro from gripper.xacro                  | -->
<!-- |    EDITING THIS FILE BY HAND IS NOT RECOMMENDED                                 | -->
<!-- =================================================================================== -->
<robot name="lwr_with_wsg50">
  <!-- Kuka LWR with Schunk WSG-50 gripper, experiment table. UHAM room F329 setup.
       05.03.2022 - change tcp frame to the original one, use pi for high accuracy transform, clean up
       23.02.2022 - add left obstacle, hide obstacle visual, change obstacle color
       29.06.2016 - catkinize'd version
       16.09.2013 - trying to calibrate the gripper precisely
       06.09.2013 - updated for Gazebo, cameras
       02.08.2013 - new file
  -->
  <material name="Black">
    <color rgba="0.0 0.0 0.0 1.0"/>
  </material>
  <material name="Blue">
    <color rgba="0.0 0.0 0.8 1.0"/>
  </material>
  <material name="Green">
    <color rgba="0.0 0.8 0.0 1.0"/>
  </material>
  <material name="Grey">
    <color rgba="0.2 0.2 0.2 1.0"/>
  </material>
  <material name="LightGrey">
    <color rgba="0.6 0.6 0.6 1.0"/>
  </material>
  <material name="DarkOrange">
    <!-- ff8c00 -->
    <color rgba="1.0 0.54 0.0 1.0"/>
  </material>
  <material name="Red">
    <color rgba="0.8 0.0 0.0 1.0"/>
  </material>
  <material name="White">
    <color rgba="1.0 1.0 1.0 1.0"/>
  </material>
  <material name="Gold">
    <color rgba="0.80  0.50  0.20  1.0"/>
  </material>
  <material name="Silver">
    <color rgba="0.90  0.91  0.98  1.0"/>
  </material>
  <material name="Copper">
    <color rgba="0.71  0.65  0.26  1.0"/>
  </material>
  <material name="Brass">
    <color rgba="0.71  0.65  0.26  1.0"/>
  </material>
  <!-- Schunk WSG-50 gripper with Weiss DSA tactile fingers

  11.05.2017 - reformat without tabs
  11.05.2017 - updated with DSA fingers

  (c) 2017 fnh, hendrich@informatik.uni-hamburg.de

-->
  <!-- the adapter plate between KuKA and the WSG gripper, 120x60x5 mm -->
  <link name="wsg_50_adapter">
    <inertial>
      <origin rpy="0 0 0" xyz="0 0 0.0025"/>
      <mass value="0.05"/>
      <inertia ixx="1" ixy="0.00" ixz="0.00" iyy="1" iyz="0.00" izz="1"/>
    </inertial>
    <visual>
      <origin rpy="0 0 0" xyz="0 0 0.0025"/>
      <geometry>
        <box size="0.12 0.06 0.005"/>
      </geometry>
      <material name="LightGrey"/>
    </visual>
    <collision>
      <origin rpy="0 0 0" xyz="0 0 0.0025"/>
      <geometry>
        <box size="0.12 0.06 0.005"/>
      </geometry>
    </collision>
  </link>
  <gazebo reference="wsg_50_adapter">
    <material>Gazebo/WhiteGlow</material>
    <turnGravityOff>false</turnGravityOff>
    <selfCollide>false</selfCollide>
    <!-- kp: stiffness kd: damping mu1, mu2: friction -->
    <mu1>100.0</mu1>
    <mu2>100.0</mu2>
    <kp>1000000.0</kp>
    <kd>1.0</kd>
  </gazebo>

  <joint name="wsg_50_gripper_anterior_gripper_joint" type="fixed">
    <origin rpy="0 0 0" xyz="0.008086 0.000091 0.005"/>
    <parent link="wsg_50_adapter"/>
    <child link="wsg_50_gripper_base_link"/>
  </joint>
  <!-- BASE LINK -->
  <link name="wsg_50_gripper_base_link">
    <inertial>
      <mass value="0.25"/>
      <origin xyz="0 0 0"/>
      <inertia ixx="1.0" ixy="0.0" ixz="0.0" iyy="1.0" iyz="0.0" izz="1.0"/>
    </inertial>
    <visual>
      <origin rpy="0 0 0" xyz="0.0 0 0"/>
      <geometry>
        <mesh filename="meshes/WSG50_110.stl" scale="1 1 1"/>
      </geometry>
      <material name="grey">
        <color rgba="0.5 0.5 0.5 1"/>
      </material>
    </visual>
    <collision>
      <origin rpy="0 0 0" xyz="0.0 0 0"/>
      <geometry>
        <mesh filename="meshes/WSG50_110.stl" scale="1 1 1"/>
      </geometry>
    </collision>
  </link>
  <gazebo reference="wsg_50_gripper_base_link">
    <material>Gazebo/Grey</material>
    <turnGravityOff>false</turnGravityOff>
  </gazebo>
  <!-- GRIPPER LEFT -->
  <joint name="wsg_50_gripper_base_joint_gripper_left" type="prismatic">
    <limit effort="1.0" lower="-0.055" upper="-0.0027" velocity="1.0"/>
    <origin rpy="0 0 0" xyz="0 0 0"/>
    <!--origin xyz="-0.0067 0 0.049" rpy="0 0 0" /-->
    <parent link="wsg_50_gripper_base_link"/>
    <child link="wsg_50_gripper_gripper_left"/>
    <dynamics damping="100" friction="100"/>
    <axis xyz="1 0 0"/>
  </joint>
  <transmission name="wsg_50_gripper_base_trans_left" type="pr2_mechanism_model/SimpleTransmission">
    <actuator name="wsg_50_gripper_base_motor_left"/>
    <joint name="wsg_50_gripper_base_joint_gripper_left"/>
    <mechanicalReduction>1</mechanicalReduction>
    <motorTorqueConstant>1</motorTorqueConstant>
  </transmission>
  <link name="wsg_50_gripper_gripper_left">
    <inertial>
      <mass value="0.1"/>
      <origin xyz="0 0 0"/>
      <inertia ixx="1.0" ixy="0.0" ixz="0.0" iyy="1.0" iyz="0.0" izz="1.0"/>
    </inertial>
    <visual>
      <origin rpy="0 0 0" xyz="0.0 0 0"/>
      <geometry>
        <mesh filename="meshes/GUIDE_WSG50_110.stl" scale="0.001 0.001 0.001"/>
      </geometry>
      <material name="black">
        <color rgba="0 0 0 1"/>
      </material>
    </visual>
    <collision>
      <origin rpy="0 0 0" xyz="0 0 0"/>
      <geometry>
        <mesh filename="meshes/GUIDE_WSG50_110.stl" scale="0.001 0.001 0.001"/>
      </geometry>
    </collision>
    <contact_coefficients kd="1.0" kp="1000.0" mu="0"/>
  </link>
  <gazebo reference="wsg_50_gripper_gripper_left">
    <material>Gazebo/Blue</material>
    <turnGravityOff>false</turnGravityOff>
  </gazebo>
  <!-- LEFT FINGER -->
  <joint name="wsg_50_gripper_guide_joint_finger_left" type="fixed">
    <origin rpy="0 0 0" xyz="-0.009 0 0.0816"/>
    <!-- manual alignment, fnh -->
    <parent link="wsg_50_gripper_gripper_left"/>
    <child link="wsg_50_gripper_finger_left"/>
  </joint>
  <link name="wsg_50_gripper_finger_left">
    <inertial>
      <mass value="0.1"/>
      <origin xyz="0 0 0"/>
      <inertia ixx="1.0" ixy="0.0" ixz="0.0" iyy="1.0" iyz="0.0" izz="1.0"/>
    </inertial>
    <visual>
      <origin rpy="0 0 0" xyz="0.0 0 0"/>
      <geometry>
        <mesh filename="meshes/WSG-DSA.stl" scale="0.001 0.001 0.001"/>
      </geometry>
      <material name="black">
        <color rgba="0 0 0 1"/>
      </material>
    </visual>
    <collision>
      <origin rpy="0 0 0" xyz="0 0 0"/>
      <geometry>
        <mesh filename="meshes/WSG-DSA.stl" scale="0.001 0.001 0.001"/>
      </geometry>
    </collision>
    <contact_coefficients kd="1.0" kp="1000.0" mu="0"/>
  </link>
  <gazebo reference="wsg_50_gripper_finger_left">
    <material>Gazebo/Blue</material>
    <turnGravityOff>false</turnGravityOff>
  </gazebo>
  <!-- GRIPPER RIGHT -->
  <joint name="wsg_50_gripper_base_joint_gripper_right" type="prismatic">
    <limit effort="1.0" lower="0.0027" upper="0.055" velocity="1.0"/>
    <origin rpy="0 0 3.14159265359" xyz="0 0 0"/>
    <parent link="wsg_50_gripper_base_link"/>
    <child link="wsg_50_gripper_gripper_right"/>
    <axis xyz="-1 0 0"/>
    <dynamics damping="100" friction="100"/>
  </joint>
  <transmission name="wsg_50_gripper_base_trans_right" type="pr2_mechanism_model/SimpleTransmission">
    <actuator name="wsg_50_gripper_base_motor_right"/>
    <joint name="wsg_50_gripper_base_joint_gripper_right"/>
    <mechanicalReduction>1</mechanicalReduction>
    <motorTorqueConstant>1</motorTorqueConstant>
  </transmission>
  <link name="wsg_50_gripper_gripper_right">
    <inertial>
      <mass value="0.1"/>
      <origin xyz="0 0 0"/>
      <inertia ixx="1.0" ixy="0.0" ixz="0.0" iyy="1.0" iyz="0.0" izz="1.0"/>
    </inertial>
    <visual>
      <origin rpy="0 0 0" xyz="0.0 0 0"/>
      <geometry>
        <mesh filename="meshes/GUIDE_WSG50_110.stl" scale="0.001 0.001 0.001"/>
      </geometry>
      <material name="black">
        <color rgba="0 0 0 1"/>
      </material>
    </visual>
    <collision>
      <origin rpy="0 0 0" xyz="0 0 0"/>
      <geometry>
        <mesh filename="meshes/GUIDE_WSG50_110.stl" scale="0.001 0.001 0.001"/>
      </geometry>
    </collision>
    <contact_coefficients kd="1.0" kp="1000.0" mu="0"/>
  </link>
  <gazebo reference="gripper_right">
    <material>Gazebo/White</material>
    <turnGravityOff>false</turnGravityOff>
  </gazebo>
  <!-- RIGHT FINGER -->
  <joint name="wsg_50_gripper_guide_joint_finger_right" type="fixed">
    <origin rpy="0 0 0" xyz="-0.009 0 0.0816"/>
    <!-- manual alignment, fnh -->
    <parent link="wsg_50_gripper_gripper_right"/>
    <child link="wsg_50_gripper_finger_right"/>
  </joint>
  <link name="wsg_50_gripper_finger_right">
    <inertial>
      <mass value="0.1"/>
      <origin xyz="0 0 0"/>
      <inertia ixx="1.0" ixy="0.0" ixz="0.0" iyy="1.0" iyz="0.0" izz="1.0"/>
    </inertial>
    <visual>
      <origin rpy="0 0 0" xyz="0.0 0 0"/>
      <geometry>
        <mesh filename="meshes/WSG-DSA.stl" scale="0.001 0.001 0.001"/>
      </geometry>
      <material name="black">
        <color rgba="0 0 0 1"/>
      </material>
    </visual>
    <collision>
      <origin rpy="0 0 0" xyz="0 0 0"/>
      <geometry>
        <mesh filename="meshes/WSG-DSA.stl" scale="0.001 0.001 0.001"/>
      </geometry>
    </collision>
    <contact_coefficients kd="1.0" kp="1000.0" mu="0"/>
  </link>
  <gazebo reference="wsg_50_gripper_finger_right">
    <material>Gazebo/White</material>
    <turnGravityOff>false</turnGravityOff>
  </gazebo>
</robot>

<mujoco>
    <compiler 
    meshdir="/data/robosuite_manipulation/robosuite/robosuite/models/assets/grippers/wsg_50/" 
    balanceinertia="true" 
    discardvisual="false" />
</mujoco>
