<mujoco model="lwr">
    <compiler angle="radian" />
    <size njmax="500" nconmax="100" />
    <asset>
        <mesh name="arm_base_convex" file="arm_base_convex.stl" />
        <mesh name="arm_segment_a_convex" file="arm_segment_a_convex.stl" />
        <mesh name="arm_segment_b_convex" file="arm_segment_b_convex.stl" />
        <mesh name="arm_segment_last" file="arm_segment_last.stl" />
        <mesh name="arm_wrist_convex" file="arm_wrist_convex.stl" />
    </asset>
    <worldbody>
        <geom size="1.3 1 0.4" pos="-0.31 -0.19 0.4" quat="0.707107 0 0 -0.707107" type="box" rgba="1 1 1 1" />
        <geom size="1.5 0.5 1" pos="-0.81 -0.59 1.1" quat="0.707107 0 0 -0.707107" type="box" rgba="0.2 0.2 0.2 1" />
        <geom size="0.75 0.5 1" pos="0.2 -1.25 1.1" quat="0.707107 0 0 -0.707107" type="box" rgba="0.2 0.2 0.2 1" />
        <geom size="0.1375 0.1375 0.007" pos="0 0 0.8071" type="box" rgba="0.6 0.6 0.6 1" />
        <geom pos="0 0 0.8142" type="mesh" rgba="1 0.487 0 1" mesh="arm_base_convex" />
        <body name="lwr_arm_1_link" pos="0 0 0.9242">
            <inertial pos="0 -0.06 0.13" mass="2" diaginertia="0.1 0.1 0.1" />
            <joint name="lwr_arm_0_joint" pos="0 0 0" axis="0 0 1" limited="true" range="-2.96706 2.96706" damping="30" />
            <geom type="mesh" rgba="1 0.487 0 1" mesh="arm_segment_a_convex" />
            <body name="lwr_arm_2_link" pos="0 0 0.2" quat="0.707107 -0.707107 0 0">
                <inertial pos="0 0.06 0.07" mass="2" diaginertia="0.1 0.1 0.1" />
                <joint name="lwr_arm_1_joint" pos="0 0 0" axis="0 0 1" limited="true" range="-2.0944 2.0944" damping="20" frictionloss="10" />
                <geom pos="0 -0.2 0" quat="0.707107 -0.707107 0 0" type="mesh" rgba="1 0.487 0 1" mesh="arm_segment_b_convex" />
                <body name="lwr_arm_3_link" pos="0 -0.2 0" quat="0.707107 0.707107 0 0">
                    <inertial pos="0 0.06 0.13" mass="2" diaginertia="0.1 0.1 0.1" />
                    <joint name="lwr_arm_2_joint" pos="0 0 0" axis="0 0 1" limited="true" range="-2.96706 2.96706" damping="30" />
                    <geom quat="0 0 0 1" type="mesh" rgba="1 0.487 0 1" mesh="arm_segment_a_convex" />
                    <body name="lwr_arm_4_link" pos="0 0 0.2" quat="0.707107 0.707107 0 0">
                        <inertial pos="0 -0.06 0.07" mass="2" diaginertia="0.1 0.1 0.1" />
                        <joint name="lwr_arm_3_joint" pos="0 0 0" axis="0 0 1" limited="true" range="-2.0944 2.0944" damping="30" />
                        <geom pos="0 0.2 0" quat="0 0 0.707107 -0.707107" type="mesh" rgba="1 0.487 0 1" mesh="arm_segment_b_convex" />
                        <body name="lwr_arm_5_link" pos="0 0.2 0" quat="0.707107 -0.707107 0 0">
                            <inertial pos="0 0 0.124" mass="2" diaginertia="0.1 0.1 0.1" />
                            <joint name="lwr_arm_4_joint" pos="0 0 0" axis="0 0 1" limited="true" range="-2.96706 2.96706" damping="30" />
                            <geom type="mesh" rgba="1 0.487 0 1" mesh="arm_segment_last" />
                            <body name="lwr_arm_6_link" pos="0 0 0.19" quat="0.707107 -0.707107 0 0">
                                <inertial pos="0 0 0.0625" mass="0.2" diaginertia="0.1 0.1 0.1" />
                                <joint name="lwr_arm_5_joint" pos="0 0 0" axis="0 0 1" limited="true" range="-2.0944 2.0944" damping="30" />
                                <geom quat="0.707107 0.707107 0 0" type="mesh" rgba="0.3 0.3 0.3 1" mesh="arm_wrist_convex" />
                                <body name="lwr_arm_7_link" pos="0 -0.078 0" quat="0.707107 0.707107 0 0">
                                    <inertial pos="0 0 0.002" mass="0.25" diaginertia="2 2 2" />
                                    <joint name="lwr_arm_6_joint" pos="0 0 0" axis="0 0 1" limited="true" range="-2.96706 2.96706" damping="30" />
                                    <geom size="0.0315 0.01" pos="0 0 -0.01" quat="0.92388 0 0 -0.382683" type="cylinder" rgba="0.3 0.3 0.3 1" />
                                    <geom size="0.0315 0.005" pos="0 0 0.005" type="cylinder" rgba="0 0 0 1" />
                                </body>
                            </body>
                        </body>
                    </body>
                </body>
            </body>
        </body>
    </worldbody>
</mujoco>
