<mujoco model="wsg50_hand">
    <asset>
        <mesh name="WSG50_110" file="meshes/wsg_50/WSG50_110.stl" />
        <mesh name="GUIDE_WSG50_110" file="meshes/wsg_50/GUIDE_WSG50_110.stl" scale="0.001 0.001 0.001" />
        <mesh name="WSG-DSA" file="meshes/wsg_50/WSG-DSA.stl" scale="0.001 0.001 0.001" />
    </asset>
    <actuator>
        <position ctrllimited="true" ctrlrange="-0.047 0" joint="finger_joint1" kp="1000" name="finger_j1" forcelimited="true" forcerange="-20 20"/>
        <position ctrllimited="true" ctrlrange="0 0.047" joint="finger_joint2" kp="1000" name="finger_j2" forcelimited="true" forcerange="-20 20"/>
    </actuator>
    <worldbody>
        <body name="lwr_arm_1_link" pos="0 0 0.9242">                
            <body name="lwr_arm_2_link" pos="0 0 0.2" quat="0.707107 -0.707107 0 0">                       
                <body name="lwr_arm_3_link" pos="0 -0.2 0" quat="0.707107 0.707107 0 0">                           
                    <body name="lwr_arm_4_link" pos="0 0 0.2" quat="0.707107 0.707107 0 0">                               
                        <body name="lwr_arm_5_link" pos="0 0.2 0" quat="0.707107 -0.707107 0 0">
                            <body name="lwr_arm_6_link" pos="0 0 0.19" quat="0.707107 -0.707107 0 0">                                        
                                <body name="lwr_arm_7_link" pos="0 -0.078 0" quat="0.707107 0.707107 0 0">   
                                    <site name="ft_frame" pos="0 0 0" size="0.01 0.01 0.01" rgba="1 0 0 1" type="sphere" group="1" />

                                    <!-- This site was added for visualization. -->
                                    <body name="eef" pos="0 0 -0.27" quat="0 1 0 0">
                                        <site name="grip_site" pos="0 0 0" size="0.01 0.01 0.01" rgba="1 0 0 0.5" type="sphere" group="1"/>
                                        <site name="ee_x" pos="0.1 0 0" size="0.005 .1"  quat="0.707105  0 0.707108 0 " rgba="1 0 0 0" type="cylinder" group="1"/>
                                        <site name="ee_y" pos="0 0.1 0" size="0.005 .1" quat="0.707105 0.707108 0 0" rgba="0 1 0 0" type="cylinder" group="1"/>
                                        <site name="ee_z" pos="0 0 0.1" size="0.005 .1" quat="1 0 0 0" rgba="0 0 1 0" type="cylinder" group="1"/>
                                        <!-- This site was added for visualization. -->
                                        <site name="grip_site_cylinder" pos="0 0 0" size="0.005 10" rgba="0 1 0 0.3" type="cylinder" group="1"/>
                                    </body>       
                                    <geom size="0.06 0.03 0.0025" pos="0 0 0.0125" quat="0.707107 0 0 -0.707107" type="box" rgba="0.6 0.6 0.6 1" />
                                    <geom pos="9.1e-05 -0.008086 0.015" quat="0.707107 0 0 -0.707107" type="mesh" mesh="WSG50_110" />
                                    <body name="gripper_left" pos="9.1e-05 -0.008086 0.015" quat="0.707107 0 0 -0.707107">
                                        <inertial pos="-0.0045 0 0.0408" quat="0.998492 0 -0.0548974 0" mass="0.2" diaginertia="2.00034 2.00034 2" />
                                        <joint name="finger_joint1" pos="0 0 0" axis="1 0 0" type="slide" limited="true" range="-0.055 -0.0027" damping="100" frictionloss="100" />
                                        <geom type="mesh" rgba="0 0 0 1" name = 'left_finger_collision' mesh="GUIDE_WSG50_110" />
                                        <geom pos="-0.009 0 0.0816" type="mesh" rgba="0 0 0 1" name ='left_finger_pad' mesh="WSG-DSA" />
                                    </body>
                                    <body name="gripper_right" pos="9.1e-05 -0.008086 0.015" quat="0.707107 0 0 0.707107">
                                        <inertial pos="-0.0045 0 0.0408" quat="0.998492 0 -0.0548974 0" mass="0.2" diaginertia="2.00034 2.00034 2" />
                                        <joint name="finger_joint2" pos="0 0 0" axis="-1 0 0" type="slide" limited="true" range="0.0027 0.055" damping="100" frictionloss="100" />
                                        <geom type="mesh" rgba="0 0 0 1" name = 'right_finger_collision' mesh="GUIDE_WSG50_110" />
                                        <geom pos="-0.009 0 0.0816" type="mesh" rgba="0 0 0 1" name ='right_finger_pad' mesh="WSG-DSA" />
                                    </body>
                                </body>
                            </body>
                        </body>
                    </body>
                </body>
            </body>
        </body>
    </worldbody>
    <!-- <sensor>
        <force name="force_ee" site="ft_frame"/>
        <torque name="torque_ee" site="ft_frame"/>
    </sensor> -->
</mujoco>
